<?xml version="1.0" ?>
<!-- =================================================================================== -->
<!-- |    This document was autogenerated by xacro from cheetah.urdf.xacro             | -->
<!-- |    EDITING THIS FILE BY HAND IS NOT RECOMMENDED                                 | -->
<!-- =================================================================================== -->
<robot name="cheetah_description">
  <!-- joint limits -->
  <!-- <xacro:property name="damping" value="0"/>
    <xacro:property name="friction" value="0"/>
    <xacro:property name="hip_max" value="120"/>
    <xacro:property name="hip_min" value="-120"/>
    <xacro:property name="hip_velocity_max" value="52.4"/>
    <xacro:property name="hip_torque_max" value="20"/>
    <xacro:property name="thigh_max" value="270"/>
    <xacro:property name="thigh_min" value="-270"/>
    <xacro:property name="thigh_velocity_max" value="28.6"/>
    <xacro:property name="thigh_torque_max" value="55"/>
    <xacro:property name="calf_max" value="155"/>
    <xacro:property name="calf_min" value="-155"/>
    <xacro:property name="calf_velocity_max" value="28.6"/>
    <xacro:property name="calf_torque_max" value="55"/> -->
  <material name="black">
    <color rgba="0.0 0.0 0.0 1.0"/>
  </material>
  <material name="blue">
    <color rgba="0.0 0.0 0.8 1.0"/>
  </material>
  <material name="green">
    <color rgba="0.0 0.8 0.0 1.0"/>
  </material>
  <material name="grey">
    <color rgba="0.2 0.2 0.2 1.0"/>
  </material>
  <material name="silver">
    <color rgba="0.9137254901960784 0.9137254901960784 0.8470588235294118 1.0"/>
  </material>
  <material name="orange">
    <color rgba="1.0 0.4235294117647059 0.0392156862745098 1.0"/>
  </material>
  <material name="brown">
    <color rgba="0.8705882352941177 0.8117647058823529 0.7647058823529411 1.0"/>
  </material>
  <material name="white_gray">
    <color rgba="0.8235294117647058 0.8235294117647058 0.8235294117647058 1.0"/>
  </material>
  <material name="gold">
    <color rgba="0.8117647058823529 0.6784313725490196 0.30196078431372547 1.0"/>
  </material>
  <material name="white_blue">
    <color rgba="0.4627450980392157 0.8 0.9921568627450981 1.0"/>
  </material>
  <material name="white_black">
    <color rgba="0.49411764705882355 0.49411764705882355 0.49411764705882355 1.0"/>
  </material>
  <material name="red">
    <color rgba="0.8 0.0 0.0 1.0"/>
  </material>
  <material name="white">
    <color rgba="1.0 1.0 1.0 1.0"/>
  </material>
  <!-- Debug mode will hung up the robot, use "true" or "false" to switch it. -->
  <!-- <link name="base_link">
        <visual>
            <origin rpy="0 0 0" xyz="0 0 0"/>
            <geometry>
                <box size="0.001 0.001 0.001"/>
            </geometry>
        </visual>
    </link>

    <joint name="floating_base" type="fixed">
        <origin rpy="0 0 0" xyz="0 0 0"/>
        <parent link="base_link"/>
        <child link="trunk"/>
    </joint> -->
  <link name="trunk"/>
  <link name="trunk_interia">
    <visual>
      <origin rpy="0 0 0" xyz="0 0 0"/>
      <geometry>
        <mesh filename="../meshes/trunk.STL" scale="1 1 1"/>
      </geometry>
      <material name="white_gray"/>
    </visual>
    <collision>
      <origin rpy="0 0 0" xyz="0 0 0"/>
      <geometry>
        <!-- <mesh filename="../meshes/trunk.STL" scale="1 1 1"/> -->
        <box size="0.3 0.2 0.093"/>
      </geometry>
    </collision>
    <inertial>
      <origin rpy="0 0 0" xyz="0.0 0.0 0.0"/>
      <mass value="3.3"/>
      <inertia ixx="0.011253" ixy="0" ixz="0.0" iyy="0.036203" iyz="-0.0" izz="0.042673"/>
    </inertial>
  </link>
  <joint name="trunk_to_trunk_inertia" type="fixed">
    <origin rpy="0 0 0" xyz="0 0 0"/>
    <parent link="trunk"/>
    <child link="trunk_interia"/>
  </joint>
  <!-- 
    <joint name="imu_joint" type="fixed">
        <parent link="trunk"/>
        <child link="imu_link"/>
        <origin rpy="0 0 0" xyz="0 0 0"/>
    </joint>

    <link name="imu_link">
        <inertial>
            <mass value="0.001"/>
            <origin rpy="0 0 0" xyz="0 0 0"/>
            <inertia ixx="0.0001" ixy="0" ixz="0" iyy="0.000001" iyz="0" izz="0.0001"/>
        </inertial>
        <visual>
            <origin rpy="0 0 0" xyz="0 0 0"/>
            <geometry>
                <box size="0.001 0.001 0.001"/>
            </geometry>
            <material name="red"/>
        </visual>
        <collision>
            <origin rpy="0 0 0" xyz="0 0 0"/>
            <geometry>
                <box size=".001 .001 .001"/>
            </geometry>
        </collision>
    </link> -->
  <transmission name="RL_hip_tran">
    <type>transmission_interface/SimpleTransmission</type>
    <joint name="RL_hip_joint">
      <hardwareInterface>hardware_interface/EffortJointInterface</hardwareInterface>
    </joint>
    <actuator name="RL_hip_motor">
      <hardwareInterface>hardware_interface/EffortJointInterface</hardwareInterface>
      <mechanicalReduction>1</mechanicalReduction>
    </actuator>
  </transmission>
  <transmission name="RL_thigh_tran">
    <type>transmission_interface/SimpleTransmission</type>
    <joint name="RL_thigh_joint">
      <hardwareInterface>hardware_interface/EffortJointInterface</hardwareInterface>
    </joint>
    <actuator name="RL_thigh_motor">
      <hardwareInterface>hardware_interface/EffortJointInterface</hardwareInterface>
      <mechanicalReduction>1</mechanicalReduction>
    </actuator>
  </transmission>
  <transmission name="RL_calf_tran">
    <type>transmission_interface/SimpleTransmission</type>
    <joint name="RL_calf_joint">
      <hardwareInterface>hardware_interface/EffortJointInterface</hardwareInterface>
    </joint>
    <actuator name="RL_calf_motor">
      <hardwareInterface>hardware_interface/EffortJointInterface</hardwareInterface>
      <mechanicalReduction>1</mechanicalReduction>
    </actuator>
  </transmission>
  <!-- //////////////////////hip//////////////////// -->
  <joint name="RL_hip_joint" type="revolute">
    <!-- <joint name="${name}_hip_joint" type="continuous"> -->
    <origin rpy="0 0 0" xyz="-0.196 0.049664 0"/>
    <parent link="trunk"/>
    <child link="RL_hip"/>
    <axis xyz="1 0 0"/>
    <dynamics damping="0" friction="0"/>
    <limit effort="20" lower="-0.8726646259971648" upper="1.0471975511965976" velocity="10.6"/>
  </joint>
  <link name="RL_hip">
    <visual>
      <origin rpy="3.141592653589793 0 0" xyz="0 0 0"/>
      <geometry>
        <mesh filename="../meshes/hip.STL" scale="1 1 1"/>
      </geometry>
      <material name="gold"/>
    </visual>
    <collision>
      <!-- <origin rpy="${PI/2.0} 0 0" xyz="0 0 0"/> -->
      <!-- <xacro:if value="${(mirror_dae == True) and (front_hind_dae == True)}">
                    <origin rpy="0 0 0" xyz="0 0 0"/>
                </xacro:if>
                <xacro:if value="${(mirror_dae == False) and (front_hind_dae == True)}">
                    <origin rpy="${PI} 0 0" xyz="0 0 0"/>
                </xacro:if>
                <xacro:if value="${(mirror_dae == True) and (front_hind_dae == False)}">
                    <origin rpy="0 ${PI} 0" xyz="0 0 0"/>
                </xacro:if>
                <xacro:if value="${(mirror_dae == False) and (front_hind_dae == False)}">
                    <origin rpy="${PI} ${PI} 0" xyz="0 0 0"/>
                </xacro:if> -->
      <geometry>
        <!-- <mesh filename="../meshes/hip.STL" scale="1 1 1"/> -->
        <box size="0.09 0.08 0.093"/>
      </geometry>
    </collision>
    <inertial>
      <origin rpy="0 0 0" xyz="0.0 -0.036 0.0"/>
      <mass value="0.57"/>
      <inertia ixx="0.0007148274999999999" ixy="0.0" ixz="0.0" iyy="0.0007955774999999998" iyz="0.0" izz="0.0006887499999999999"/>
    </inertial>
  </link>
  <!-- //////////////////////thigh//////////////////// -->
  <joint name="RL_thigh_joint" type="revolute">
    <!-- <joint name="${name}_thigh_joint" type="continuous"> -->
    <origin rpy="0 0 0" xyz="0 0.077476 0"/>
    <parent link="RL_hip"/>
    <child link="RL_thigh"/>
    <axis xyz="0 1 0"/>
    <dynamics damping="0" friction="0"/>
    <limit effort="20" lower="-0.5235987755982988" upper="3.9269908169872414" velocity="10.6"/>
  </joint>
  <link name="RL_thigh">
    <visual>
      <origin rpy="3.141592653589793 3.141592653589793 0" xyz="0 0 0"/>
      <geometry>
        <mesh filename="../meshes/thigh.STL" scale="1 1 1"/>
      </geometry>
      <material name="white_blue"/>
    </visual>
    <collision>
      <!-- <xacro:if value="${mirror_dae == True}">
                    <origin rpy="0 0 0" xyz="0 0 0"/>                 
                </xacro:if>
                <xacro:if value="${mirror_dae == False}">
                    <origin rpy="${PI} ${PI} 0" xyz="0 0 0"/>
                </xacro:if> -->
      <origin rpy="0 0 0" xyz="0 0 -0.11"/>
      <geometry>
        <box size="0.043 0.034 0.22"/>
        <!-- <mesh filename="../meshes/thigh.STL" scale="1 1 1"/> -->
      </geometry>
      <material name="white_blue"/>
    </collision>
    <inertial>
      <origin rpy="0 0 0" xyz="0.0 -0.016 -0.11"/>
      <mass value="0.634"/>
      <inertia ixx="0.0026182086666666662" ixy="0.0" ixz="0.0" iyy="0.0026548221666666664" iyz="0.0" izz="0.00015876416666666665"/>
    </inertial>
  </link>
  <!-- //////////////////////calf//////////////////// -->
  <joint name="RL_calf_joint" type="revolute">
    <!-- <joint name="${name}_calf_joint" type="continuous"> -->
    <origin rpy="0 0 0" xyz="0 0 -0.2115"/>
    <parent link="RL_thigh"/>
    <child link="RL_calf"/>
    <axis xyz="0 1 0"/>
    <dynamics damping="0" friction="0"/>
    <!-- <limit effort="${calf_torque_max}" velocity="${calf_velocity_max}" lower="${calf_min*PI/180.0}" upper="${calf_max*PI/180.0}"/> -->
    <limit effort="20" lower="-3.141592653589793" upper="3.141592653589793" velocity="10.6"/>
  </joint>
  <link name="RL_calf">
    <visual>
      <origin rpy="0 0 0" xyz="0.0 0.009 0.0"/>
      <geometry>
        <mesh filename="../meshes/calf.STL" scale="1 1 1"/>
      </geometry>
      <material name="white_blue"/>
    </visual>
    <collision>
      <origin rpy="0 0 0" xyz="0.0 0.0 -0.1"/>
      <geometry>
        <box size="0.016 0.016 0.2"/>
        <!-- <mesh filename="../meshes/calf.STL" scale="1 1 1"/> -->
      </geometry>
    </collision>
    <inertial>
      <origin rpy="0 0 0" xyz="0.0 0.0 0.0"/>
      <mass value="0.064"/>
      <inertia ixx="0.0002146986666666667" ixy="0.0" ixz="0.0" iyy="0.0002146986666666667" iyz="0.0" izz="2.7306666666666666e-06"/>
    </inertial>
  </link>
  <!-- //////////////////////foot//////////////////// -->
  <joint name="RL_foot_fixed" type="fixed">
    <origin rpy="0 0 0" xyz="0 0 -0.23039"/>
    <parent link="RL_calf"/>
    <child link="RL_foot"/>
  </joint>
  <link name="RL_foot">
    <visual>
      <origin rpy="0 0 0" xyz="0 0.018 0.02"/>
      <geometry>
        <mesh filename="../meshes/foot.STL" scale="1 1 1"/>
      </geometry>
      <material name="white_black"/>
    </visual>
    <collision>
      <origin rpy="0 0 0" xyz="0 0.0 0.025"/>
      <geometry>
        <!-- <mesh filename="../meshes/foot.STL" scale="1 1 1"/> -->
        <sphere radius="0.025"/>
      </geometry>
    </collision>
    <inertial>
      <origin rpy="0 0 0" xyz="0.0 0.0 0"/>
      <mass value="0.15"/>
      <inertia ixx="4.2134999999999996e-05" ixy="0.0" ixz="0.0" iyy="4.2134999999999996e-05" iyz="0.0" izz="4.2134999999999996e-05"/>
    </inertial>
  </link>
  <transmission name="FL_hip_tran">
    <type>transmission_interface/SimpleTransmission</type>
    <joint name="FL_hip_joint">
      <hardwareInterface>hardware_interface/EffortJointInterface</hardwareInterface>
    </joint>
    <actuator name="FL_hip_motor">
      <hardwareInterface>hardware_interface/EffortJointInterface</hardwareInterface>
      <mechanicalReduction>1</mechanicalReduction>
    </actuator>
  </transmission>
  <transmission name="FL_thigh_tran">
    <type>transmission_interface/SimpleTransmission</type>
    <joint name="FL_thigh_joint">
      <hardwareInterface>hardware_interface/EffortJointInterface</hardwareInterface>
    </joint>
    <actuator name="FL_thigh_motor">
      <hardwareInterface>hardware_interface/EffortJointInterface</hardwareInterface>
      <mechanicalReduction>1</mechanicalReduction>
    </actuator>
  </transmission>
  <transmission name="FL_calf_tran">
    <type>transmission_interface/SimpleTransmission</type>
    <joint name="FL_calf_joint">
      <hardwareInterface>hardware_interface/EffortJointInterface</hardwareInterface>
    </joint>
    <actuator name="FL_calf_motor">
      <hardwareInterface>hardware_interface/EffortJointInterface</hardwareInterface>
      <mechanicalReduction>1</mechanicalReduction>
    </actuator>
  </transmission>
  <!-- //////////////////////hip//////////////////// -->
  <joint name="FL_hip_joint" type="revolute">
    <!-- <joint name="${name}_hip_joint" type="continuous"> -->
    <origin rpy="0 0 0" xyz="0.196 0.049664 0"/>
    <parent link="trunk"/>
    <child link="FL_hip"/>
    <axis xyz="1 0 0"/>
    <dynamics damping="0" friction="0"/>
    <limit effort="20" lower="-0.8726646259971648" upper="1.0471975511965976" velocity="10.6"/>
  </joint>
  <link name="FL_hip">
    <visual>
      <origin rpy="3.141592653589793 3.141592653589793 0" xyz="0 0 0"/>
      <geometry>
        <mesh filename="../meshes/hip.STL" scale="1 1 1"/>
      </geometry>
      <material name="gold"/>
    </visual>
    <collision>
      <!-- <origin rpy="${PI/2.0} 0 0" xyz="0 0 0"/> -->
      <!-- <xacro:if value="${(mirror_dae == True) and (front_hind_dae == True)}">
                    <origin rpy="0 0 0" xyz="0 0 0"/>
                </xacro:if>
                <xacro:if value="${(mirror_dae == False) and (front_hind_dae == True)}">
                    <origin rpy="${PI} 0 0" xyz="0 0 0"/>
                </xacro:if>
                <xacro:if value="${(mirror_dae == True) and (front_hind_dae == False)}">
                    <origin rpy="0 ${PI} 0" xyz="0 0 0"/>
                </xacro:if>
                <xacro:if value="${(mirror_dae == False) and (front_hind_dae == False)}">
                    <origin rpy="${PI} ${PI} 0" xyz="0 0 0"/>
                </xacro:if> -->
      <geometry>
        <!-- <mesh filename="../meshes/hip.STL" scale="1 1 1"/> -->
        <box size="0.09 0.08 0.093"/>
      </geometry>
    </collision>
    <inertial>
      <origin rpy="0 0 0" xyz="-0.0 -0.036 0.0"/>
      <mass value="0.57"/>
      <inertia ixx="0.0007148274999999999" ixy="0.0" ixz="0.0" iyy="0.0007955774999999998" iyz="0.0" izz="0.0006887499999999999"/>
    </inertial>
  </link>
  <!-- //////////////////////thigh//////////////////// -->
  <joint name="FL_thigh_joint" type="revolute">
    <!-- <joint name="${name}_thigh_joint" type="continuous"> -->
    <origin rpy="0 0 0" xyz="0 0.077476 0"/>
    <parent link="FL_hip"/>
    <child link="FL_thigh"/>
    <axis xyz="0 1 0"/>
    <dynamics damping="0" friction="0"/>
    <limit effort="20" lower="-0.5235987755982988" upper="3.9269908169872414" velocity="10.6"/>
  </joint>
  <link name="FL_thigh">
    <visual>
      <origin rpy="3.141592653589793 3.141592653589793 0" xyz="0 0 0"/>
      <geometry>
        <mesh filename="../meshes/thigh.STL" scale="1 1 1"/>
      </geometry>
      <material name="white_blue"/>
    </visual>
    <collision>
      <!-- <xacro:if value="${mirror_dae == True}">
                    <origin rpy="0 0 0" xyz="0 0 0"/>                 
                </xacro:if>
                <xacro:if value="${mirror_dae == False}">
                    <origin rpy="${PI} ${PI} 0" xyz="0 0 0"/>
                </xacro:if> -->
      <origin rpy="0 0 0" xyz="0 0 -0.11"/>
      <geometry>
        <box size="0.043 0.034 0.22"/>
        <!-- <mesh filename="../meshes/thigh.STL" scale="1 1 1"/> -->
      </geometry>
      <material name="white_blue"/>
    </collision>
    <inertial>
      <origin rpy="0 0 0" xyz="0.0 -0.016 -0.11"/>
      <mass value="0.634"/>
      <inertia ixx="0.0026182086666666662" ixy="0.0" ixz="0.0" iyy="0.0026548221666666664" iyz="0.0" izz="0.00015876416666666665"/>
    </inertial>
  </link>
  <!-- //////////////////////calf//////////////////// -->
  <joint name="FL_calf_joint" type="revolute">
    <!-- <joint name="${name}_calf_joint" type="continuous"> -->
    <origin rpy="0 0 0" xyz="0 0 -0.2115"/>
    <parent link="FL_thigh"/>
    <child link="FL_calf"/>
    <axis xyz="0 1 0"/>
    <dynamics damping="0" friction="0"/>
    <!-- <limit effort="${calf_torque_max}" velocity="${calf_velocity_max}" lower="${calf_min*PI/180.0}" upper="${calf_max*PI/180.0}"/> -->
    <limit effort="20" lower="-3.141592653589793" upper="3.141592653589793" velocity="10.6"/>
  </joint>
  <link name="FL_calf">
    <visual>
      <origin rpy="0 0 0" xyz="0.0 0.009 0.0"/>
      <geometry>
        <mesh filename="../meshes/calf.STL" scale="1 1 1"/>
      </geometry>
      <material name="white_blue"/>
    </visual>
    <collision>
      <origin rpy="0 0 0" xyz="0.0 0.0 -0.1"/>
      <geometry>
        <box size="0.016 0.016 0.2"/>
        <!-- <mesh filename="../meshes/calf.STL" scale="1 1 1"/> -->
      </geometry>
    </collision>
    <inertial>
      <origin rpy="0 0 0" xyz="0.0 0.0 0.0"/>
      <mass value="0.064"/>
      <inertia ixx="0.0002146986666666667" ixy="0.0" ixz="0.0" iyy="0.0002146986666666667" iyz="0.0" izz="2.7306666666666666e-06"/>
    </inertial>
  </link>
  <!-- //////////////////////foot//////////////////// -->
  <joint name="FL_foot_fixed" type="fixed">
    <origin rpy="0 0 0" xyz="0 0 -0.23039"/>
    <parent link="FL_calf"/>
    <child link="FL_foot"/>
  </joint>
  <link name="FL_foot">
    <visual>
      <origin rpy="0 0 0" xyz="0 0.018 0.02"/>
      <geometry>
        <mesh filename="../meshes/foot.STL" scale="1 1 1"/>
      </geometry>
      <material name="white_black"/>
    </visual>
    <collision>
      <origin rpy="0 0 0" xyz="0 0.0 0.025"/>
      <geometry>
        <!-- <mesh filename="../meshes/foot.STL" scale="1 1 1"/> -->
        <sphere radius="0.025"/>
      </geometry>
    </collision>
    <inertial>
      <origin rpy="0 0 0" xyz="0.0 0.0 0"/>
      <mass value="0.15"/>
      <inertia ixx="4.2134999999999996e-05" ixy="0.0" ixz="0.0" iyy="4.2134999999999996e-05" iyz="0.0" izz="4.2134999999999996e-05"/>
    </inertial>
  </link>
  <transmission name="RR_hip_tran">
    <type>transmission_interface/SimpleTransmission</type>
    <joint name="RR_hip_joint">
      <hardwareInterface>hardware_interface/EffortJointInterface</hardwareInterface>
    </joint>
    <actuator name="RR_hip_motor">
      <hardwareInterface>hardware_interface/EffortJointInterface</hardwareInterface>
      <mechanicalReduction>1</mechanicalReduction>
    </actuator>
  </transmission>
  <transmission name="RR_thigh_tran">
    <type>transmission_interface/SimpleTransmission</type>
    <joint name="RR_thigh_joint">
      <hardwareInterface>hardware_interface/EffortJointInterface</hardwareInterface>
    </joint>
    <actuator name="RR_thigh_motor">
      <hardwareInterface>hardware_interface/EffortJointInterface</hardwareInterface>
      <mechanicalReduction>1</mechanicalReduction>
    </actuator>
  </transmission>
  <transmission name="RR_calf_tran">
    <type>transmission_interface/SimpleTransmission</type>
    <joint name="RR_calf_joint">
      <hardwareInterface>hardware_interface/EffortJointInterface</hardwareInterface>
    </joint>
    <actuator name="RR_calf_motor">
      <hardwareInterface>hardware_interface/EffortJointInterface</hardwareInterface>
      <mechanicalReduction>1</mechanicalReduction>
    </actuator>
  </transmission>
  <!-- //////////////////////hip//////////////////// -->
  <joint name="RR_hip_joint" type="revolute">
    <!-- <joint name="${name}_hip_joint" type="continuous"> -->
    <origin rpy="0 0 0" xyz="-0.196 -0.049664 0"/>
    <parent link="trunk"/>
    <child link="RR_hip"/>
    <axis xyz="1 0 0"/>
    <dynamics damping="0" friction="0"/>
    <limit effort="20" lower="-1.0471975511965976" upper="0.8726646259971648" velocity="10.6"/>
  </joint>
  <link name="RR_hip">
    <visual>
      <origin rpy="0 0 0" xyz="0 0 0"/>
      <geometry>
        <mesh filename="../meshes/hip.STL" scale="1 1 1"/>
      </geometry>
      <material name="gold"/>
    </visual>
    <collision>
      <!-- <origin rpy="${PI/2.0} 0 0" xyz="0 0 0"/> -->
      <!-- <xacro:if value="${(mirror_dae == True) and (front_hind_dae == True)}">
                    <origin rpy="0 0 0" xyz="0 0 0"/>
                </xacro:if>
                <xacro:if value="${(mirror_dae == False) and (front_hind_dae == True)}">
                    <origin rpy="${PI} 0 0" xyz="0 0 0"/>
                </xacro:if>
                <xacro:if value="${(mirror_dae == True) and (front_hind_dae == False)}">
                    <origin rpy="0 ${PI} 0" xyz="0 0 0"/>
                </xacro:if>
                <xacro:if value="${(mirror_dae == False) and (front_hind_dae == False)}">
                    <origin rpy="${PI} ${PI} 0" xyz="0 0 0"/>
                </xacro:if> -->
      <geometry>
        <!-- <mesh filename="../meshes/hip.STL" scale="1 1 1"/> -->
        <box size="0.09 0.08 0.093"/>
      </geometry>
    </collision>
    <inertial>
      <origin rpy="0 0 0" xyz="0.0 0.036 0.0"/>
      <mass value="0.57"/>
      <inertia ixx="0.0007148274999999999" ixy="0.0" ixz="0.0" iyy="0.0007955774999999998" iyz="0.0" izz="0.0006887499999999999"/>
    </inertial>
  </link>
  <!-- //////////////////////thigh//////////////////// -->
  <joint name="RR_thigh_joint" type="revolute">
    <!-- <joint name="${name}_thigh_joint" type="continuous"> -->
    <origin rpy="0 0 0" xyz="0 -0.077476 0"/>
    <parent link="RR_hip"/>
    <child link="RR_thigh"/>
    <axis xyz="0 1 0"/>
    <dynamics damping="0" friction="0"/>
    <limit effort="20" lower="-0.5235987755982988" upper="3.9269908169872414" velocity="10.6"/>
  </joint>
  <link name="RR_thigh">
    <visual>
      <origin rpy="0 0 0" xyz="0 0 0"/>
      <geometry>
        <mesh filename="../meshes/thigh.STL" scale="1 1 1"/>
      </geometry>
      <material name="white_blue"/>
    </visual>
    <collision>
      <!-- <xacro:if value="${mirror_dae == True}">
                    <origin rpy="0 0 0" xyz="0 0 0"/>                 
                </xacro:if>
                <xacro:if value="${mirror_dae == False}">
                    <origin rpy="${PI} ${PI} 0" xyz="0 0 0"/>
                </xacro:if> -->
      <origin rpy="0 0 0" xyz="0 0 -0.11"/>
      <geometry>
        <box size="0.043 0.034 0.22"/>
        <!-- <mesh filename="../meshes/thigh.STL" scale="1 1 1"/> -->
      </geometry>
      <material name="white_blue"/>
    </collision>
    <inertial>
      <origin rpy="0 0 0" xyz="0.0 0.016 -0.11"/>
      <mass value="0.634"/>
      <inertia ixx="0.0026182086666666662" ixy="0.0" ixz="0.0" iyy="0.0026548221666666664" iyz="0.0" izz="0.00015876416666666665"/>
    </inertial>
  </link>
  <!-- //////////////////////calf//////////////////// -->
  <joint name="RR_calf_joint" type="revolute">
    <!-- <joint name="${name}_calf_joint" type="continuous"> -->
    <origin rpy="0 0 0" xyz="0 0 -0.2115"/>
    <parent link="RR_thigh"/>
    <child link="RR_calf"/>
    <axis xyz="0 1 0"/>
    <dynamics damping="0" friction="0"/>
    <!-- <limit effort="${calf_torque_max}" velocity="${calf_velocity_max}" lower="${calf_min*PI/180.0}" upper="${calf_max*PI/180.0}"/> -->
    <limit effort="20" lower="-3.141592653589793" upper="3.141592653589793" velocity="10.6"/>
  </joint>
  <link name="RR_calf">
    <visual>
      <origin rpy="0 0 0" xyz="0.0 0.009 0.0"/>
      <geometry>
        <mesh filename="../meshes/calf.STL" scale="1 1 1"/>
      </geometry>
      <material name="white_blue"/>
    </visual>
    <collision>
      <origin rpy="0 0 0" xyz="0.0 0.0 -0.1"/>
      <geometry>
        <box size="0.016 0.016 0.2"/>
        <!-- <mesh filename="../meshes/calf.STL" scale="1 1 1"/> -->
      </geometry>
    </collision>
    <inertial>
      <origin rpy="0 0 0" xyz="0.0 0.0 0.0"/>
      <mass value="0.064"/>
      <inertia ixx="0.0002146986666666667" ixy="0.0" ixz="0.0" iyy="0.0002146986666666667" iyz="0.0" izz="2.7306666666666666e-06"/>
    </inertial>
  </link>
  <!-- //////////////////////foot//////////////////// -->
  <joint name="RR_foot_fixed" type="fixed">
    <origin rpy="0 0 0" xyz="0 0 -0.23039"/>
    <parent link="RR_calf"/>
    <child link="RR_foot"/>
  </joint>
  <link name="RR_foot">
    <visual>
      <origin rpy="0 0 0" xyz="0 0.018 0.02"/>
      <geometry>
        <mesh filename="../meshes/foot.STL" scale="1 1 1"/>
      </geometry>
      <material name="white_black"/>
    </visual>
    <collision>
      <origin rpy="0 0 0" xyz="0 0.0 0.025"/>
      <geometry>
        <!-- <mesh filename="../meshes/foot.STL" scale="1 1 1"/> -->
        <sphere radius="0.025"/>
      </geometry>
    </collision>
    <inertial>
      <origin rpy="0 0 0" xyz="0.0 0.0 0"/>
      <mass value="0.15"/>
      <inertia ixx="4.2134999999999996e-05" ixy="0.0" ixz="0.0" iyy="4.2134999999999996e-05" iyz="0.0" izz="4.2134999999999996e-05"/>
    </inertial>
  </link>
  <transmission name="FR_hip_tran">
    <type>transmission_interface/SimpleTransmission</type>
    <joint name="FR_hip_joint">
      <hardwareInterface>hardware_interface/EffortJointInterface</hardwareInterface>
    </joint>
    <actuator name="FR_hip_motor">
      <hardwareInterface>hardware_interface/EffortJointInterface</hardwareInterface>
      <mechanicalReduction>1</mechanicalReduction>
    </actuator>
  </transmission>
  <transmission name="FR_thigh_tran">
    <type>transmission_interface/SimpleTransmission</type>
    <joint name="FR_thigh_joint">
      <hardwareInterface>hardware_interface/EffortJointInterface</hardwareInterface>
    </joint>
    <actuator name="FR_thigh_motor">
      <hardwareInterface>hardware_interface/EffortJointInterface</hardwareInterface>
      <mechanicalReduction>1</mechanicalReduction>
    </actuator>
  </transmission>
  <transmission name="FR_calf_tran">
    <type>transmission_interface/SimpleTransmission</type>
    <joint name="FR_calf_joint">
      <hardwareInterface>hardware_interface/EffortJointInterface</hardwareInterface>
    </joint>
    <actuator name="FR_calf_motor">
      <hardwareInterface>hardware_interface/EffortJointInterface</hardwareInterface>
      <mechanicalReduction>1</mechanicalReduction>
    </actuator>
  </transmission>
  <!-- //////////////////////hip//////////////////// -->
  <joint name="FR_hip_joint" type="revolute">
    <!-- <joint name="${name}_hip_joint" type="continuous"> -->
    <origin rpy="0 0 0" xyz="0.196 -0.049664 0"/>
    <parent link="trunk"/>
    <child link="FR_hip"/>
    <axis xyz="1 0 0"/>
    <dynamics damping="0" friction="0"/>
    <limit effort="20" lower="-1.0471975511965976" upper="0.8726646259971648" velocity="10.6"/>
  </joint>
  <link name="FR_hip">
    <visual>
      <origin rpy="0 3.141592653589793 0" xyz="0 0 0"/>
      <geometry>
        <mesh filename="../meshes/hip.STL" scale="1 1 1"/>
      </geometry>
      <material name="gold"/>
    </visual>
    <collision>
      <!-- <origin rpy="${PI/2.0} 0 0" xyz="0 0 0"/> -->
      <!-- <xacro:if value="${(mirror_dae == True) and (front_hind_dae == True)}">
                    <origin rpy="0 0 0" xyz="0 0 0"/>
                </xacro:if>
                <xacro:if value="${(mirror_dae == False) and (front_hind_dae == True)}">
                    <origin rpy="${PI} 0 0" xyz="0 0 0"/>
                </xacro:if>
                <xacro:if value="${(mirror_dae == True) and (front_hind_dae == False)}">
                    <origin rpy="0 ${PI} 0" xyz="0 0 0"/>
                </xacro:if>
                <xacro:if value="${(mirror_dae == False) and (front_hind_dae == False)}">
                    <origin rpy="${PI} ${PI} 0" xyz="0 0 0"/>
                </xacro:if> -->
      <geometry>
        <!-- <mesh filename="../meshes/hip.STL" scale="1 1 1"/> -->
        <box size="0.09 0.08 0.093"/>
      </geometry>
    </collision>
    <inertial>
      <origin rpy="0 0 0" xyz="-0.0 0.036 0.0"/>
      <mass value="0.57"/>
      <inertia ixx="0.0007148274999999999" ixy="0.0" ixz="0.0" iyy="0.0007955774999999998" iyz="0.0" izz="0.0006887499999999999"/>
    </inertial>
  </link>
  <!-- //////////////////////thigh//////////////////// -->
  <joint name="FR_thigh_joint" type="revolute">
    <!-- <joint name="${name}_thigh_joint" type="continuous"> -->
    <origin rpy="0 0 0" xyz="0 -0.077476 0"/>
    <parent link="FR_hip"/>
    <child link="FR_thigh"/>
    <axis xyz="0 1 0"/>
    <dynamics damping="0" friction="0"/>
    <limit effort="20" lower="-0.5235987755982988" upper="3.9269908169872414" velocity="10.6"/>
  </joint>
  <link name="FR_thigh">
    <visual>
      <origin rpy="0 0 0" xyz="0 0 0"/>
      <geometry>
        <mesh filename="../meshes/thigh.STL" scale="1 1 1"/>
      </geometry>
      <material name="white_blue"/>
    </visual>
    <collision>
      <!-- <xacro:if value="${mirror_dae == True}">
                    <origin rpy="0 0 0" xyz="0 0 0"/>                 
                </xacro:if>
                <xacro:if value="${mirror_dae == False}">
                    <origin rpy="${PI} ${PI} 0" xyz="0 0 0"/>
                </xacro:if> -->
      <origin rpy="0 0 0" xyz="0 0 -0.11"/>
      <geometry>
        <box size="0.043 0.034 0.22"/>
        <!-- <mesh filename="../meshes/thigh.STL" scale="1 1 1"/> -->
      </geometry>
      <material name="white_blue"/>
    </collision>
    <inertial>
      <origin rpy="0 0 0" xyz="0.0 0.016 -0.11"/>
      <mass value="0.634"/>
      <inertia ixx="0.0026182086666666662" ixy="0.0" ixz="0.0" iyy="0.0026548221666666664" iyz="0.0" izz="0.00015876416666666665"/>
    </inertial>
  </link>
  <!-- //////////////////////calf//////////////////// -->
  <joint name="FR_calf_joint" type="revolute">
    <!-- <joint name="${name}_calf_joint" type="continuous"> -->
    <origin rpy="0 0 0" xyz="0 0 -0.2115"/>
    <parent link="FR_thigh"/>
    <child link="FR_calf"/>
    <axis xyz="0 1 0"/>
    <dynamics damping="0" friction="0"/>
    <!-- <limit effort="${calf_torque_max}" velocity="${calf_velocity_max}" lower="${calf_min*PI/180.0}" upper="${calf_max*PI/180.0}"/> -->
    <limit effort="20" lower="-3.141592653589793" upper="3.141592653589793" velocity="10.6"/>
  </joint>
  <link name="FR_calf">
    <visual>
      <origin rpy="0 0 0" xyz="0.0 0.009 0.0"/>
      <geometry>
        <mesh filename="../meshes/calf.STL" scale="1 1 1"/>
      </geometry>
      <material name="white_blue"/>
    </visual>
    <collision>
      <origin rpy="0 0 0" xyz="0.0 0.0 -0.1"/>
      <geometry>
        <box size="0.016 0.016 0.2"/>
        <!-- <mesh filename="../meshes/calf.STL" scale="1 1 1"/> -->
      </geometry>
    </collision>
    <inertial>
      <origin rpy="0 0 0" xyz="0.0 0.0 0.0"/>
      <mass value="0.064"/>
      <inertia ixx="0.0002146986666666667" ixy="0.0" ixz="0.0" iyy="0.0002146986666666667" iyz="0.0" izz="2.7306666666666666e-06"/>
    </inertial>
  </link>
  <!-- //////////////////////foot//////////////////// -->
  <joint name="FR_foot_fixed" type="fixed">
    <origin rpy="0 0 0" xyz="0 0 -0.23039"/>
    <parent link="FR_calf"/>
    <child link="FR_foot"/>
  </joint>
  <link name="FR_foot">
    <visual>
      <origin rpy="0 0 0" xyz="0 0.018 0.02"/>
      <geometry>
        <mesh filename="../meshes/foot.STL" scale="1 1 1"/>
      </geometry>
      <material name="white_black"/>
    </visual>
    <collision>
      <origin rpy="0 0 0" xyz="0 0.0 0.025"/>
      <geometry>
        <!-- <mesh filename="../meshes/foot.STL" scale="1 1 1"/> -->
        <sphere radius="0.025"/>
      </geometry>
    </collision>
    <inertial>
      <origin rpy="0 0 0" xyz="0.0 0.0 0"/>
      <mass value="0.15"/>
      <inertia ixx="4.2134999999999996e-05" ixy="0.0" ixz="0.0" iyy="4.2134999999999996e-05" iyz="0.0" izz="4.2134999999999996e-05"/>
    </inertial>
  </link>
</robot>

